[2024-07-10T13:24:21.076+0000] {local_task_job_runner.py:120} INFO - ::group::Pre task execution logs
[2024-07-10T13:24:21.108+0000] {taskinstance.py:2076} INFO - Dependencies all met for dep_context=non-requeueable deps ti=<TaskInstance: spaceX_project.loading_into_db scheduled__2024-07-09T00:00:00+00:00 [queued]>
[2024-07-10T13:24:21.118+0000] {taskinstance.py:2076} INFO - Dependencies all met for dep_context=requeueable deps ti=<TaskInstance: spaceX_project.loading_into_db scheduled__2024-07-09T00:00:00+00:00 [queued]>
[2024-07-10T13:24:21.119+0000] {taskinstance.py:2306} INFO - Starting attempt 2 of 6
[2024-07-10T13:24:21.134+0000] {taskinstance.py:2330} INFO - Executing <Task(PythonOperator): loading_into_db> on 2024-07-09 00:00:00+00:00
[2024-07-10T13:24:21.141+0000] {warnings.py:112} WARNING - /home/***/.local/lib/python3.12/site-packages/***/task/task_runner/standard_task_runner.py:61: DeprecationWarning: This process (pid=1420) is multi-threaded, use of fork() may lead to deadlocks in the child.
  pid = os.fork()

[2024-07-10T13:24:21.143+0000] {standard_task_runner.py:63} INFO - Started process 1422 to run task
[2024-07-10T13:24:21.144+0000] {standard_task_runner.py:90} INFO - Running: ['***', 'tasks', 'run', 'spaceX_project', 'loading_into_db', 'scheduled__2024-07-09T00:00:00+00:00', '--job-id', '590', '--raw', '--subdir', 'DAGS_FOLDER/dag.py', '--cfg-path', '/tmp/tmpt5_1tygy']
[2024-07-10T13:24:21.146+0000] {standard_task_runner.py:91} INFO - Job 590: Subtask loading_into_db
[2024-07-10T13:24:21.197+0000] {task_command.py:426} INFO - Running <TaskInstance: spaceX_project.loading_into_db scheduled__2024-07-09T00:00:00+00:00 [running]> on host afe5e479c9b4
[2024-07-10T13:24:21.290+0000] {taskinstance.py:2648} INFO - Exporting env vars: AIRFLOW_CTX_DAG_OWNER='rustam' AIRFLOW_CTX_DAG_ID='spaceX_project' AIRFLOW_CTX_TASK_ID='loading_into_db' AIRFLOW_CTX_EXECUTION_DATE='2024-07-09T00:00:00+00:00' AIRFLOW_CTX_TRY_NUMBER='2' AIRFLOW_CTX_DAG_RUN_ID='scheduled__2024-07-09T00:00:00+00:00'
[2024-07-10T13:24:21.299+0000] {taskinstance.py:430} INFO - ::endgroup::
[2024-07-10T13:24:21.339+0000] {taskinstance.py:441} INFO - ::group::Post task execution logs
[2024-07-10T13:24:21.340+0000] {taskinstance.py:2905} ERROR - Task failed with exception
Traceback (most recent call last):
  File "/home/airflow/.local/lib/python3.12/site-packages/airflow/models/taskinstance.py", line 465, in _execute_task
    result = _execute_callable(context=context, **execute_callable_kwargs)
             ^^^^^^^^^^^^^^^^^^^^^^^^^^^^^^^^^^^^^^^^^^^^^^^^^^^^^^^^^^^^^
  File "/home/airflow/.local/lib/python3.12/site-packages/airflow/models/taskinstance.py", line 432, in _execute_callable
    return execute_callable(context=context, **execute_callable_kwargs)
           ^^^^^^^^^^^^^^^^^^^^^^^^^^^^^^^^^^^^^^^^^^^^^^^^^^^^^^^^^^^^
  File "/home/airflow/.local/lib/python3.12/site-packages/airflow/models/baseoperator.py", line 401, in wrapper
    return func(self, *args, **kwargs)
           ^^^^^^^^^^^^^^^^^^^^^^^^^^^
  File "/home/airflow/.local/lib/python3.12/site-packages/airflow/operators/python.py", line 235, in execute
    return_value = self.execute_callable()
                   ^^^^^^^^^^^^^^^^^^^^^^^
  File "/home/airflow/.local/lib/python3.12/site-packages/airflow/operators/python.py", line 252, in execute_callable
    return self.python_callable(*self.op_args, **self.op_kwargs)
           ^^^^^^^^^^^^^^^^^^^^^^^^^^^^^^^^^^^^^^^^^^^^^^^^^^^^^
  File "/opt/airflow/dags/dag.py", line 57, in load_charachteristics
    conn = psycopg2.connect(
           ^^^^^^^^^^^^^^^^^
  File "/home/airflow/.local/lib/python3.12/site-packages/psycopg2/__init__.py", line 122, in connect
    conn = _connect(dsn, connection_factory=connection_factory, **kwasync)
           ^^^^^^^^^^^^^^^^^^^^^^^^^^^^^^^^^^^^^^^^^^^^^^^^^^^^^^^^^^^^^^^
psycopg2.OperationalError: connection to server at "localhost" (127.0.0.1), port 5432 failed: Connection refused
	Is the server running on that host and accepting TCP/IP connections?
connection to server at "localhost" (::1), port 5432 failed: Cannot assign requested address
	Is the server running on that host and accepting TCP/IP connections?

[2024-07-10T13:24:21.362+0000] {taskinstance.py:1206} INFO - Marking task as UP_FOR_RETRY. dag_id=spaceX_project, task_id=loading_into_db, run_id=scheduled__2024-07-09T00:00:00+00:00, execution_date=20240709T000000, start_date=20240710T132421, end_date=20240710T132421
[2024-07-10T13:24:21.382+0000] {standard_task_runner.py:110} ERROR - Failed to execute job 590 for task loading_into_db (connection to server at "localhost" (127.0.0.1), port 5432 failed: Connection refused
	Is the server running on that host and accepting TCP/IP connections?
connection to server at "localhost" (::1), port 5432 failed: Cannot assign requested address
	Is the server running on that host and accepting TCP/IP connections?
; 1422)
[2024-07-10T13:24:21.398+0000] {local_task_job_runner.py:240} INFO - Task exited with return code 1
[2024-07-10T13:24:21.415+0000] {taskinstance.py:3503} INFO - 0 downstream tasks scheduled from follow-on schedule check
[2024-07-10T13:24:21.417+0000] {local_task_job_runner.py:222} INFO - ::endgroup::
