[2024-07-10T13:23:49.475+0000] {local_task_job_runner.py:120} INFO - ::group::Pre task execution logs
[2024-07-10T13:23:49.517+0000] {taskinstance.py:2076} INFO - Dependencies all met for dep_context=non-requeueable deps ti=<TaskInstance: spaceX_project.loading_into_db scheduled__2024-07-09T00:00:00+00:00 [queued]>
[2024-07-10T13:23:49.528+0000] {taskinstance.py:2076} INFO - Dependencies all met for dep_context=requeueable deps ti=<TaskInstance: spaceX_project.loading_into_db scheduled__2024-07-09T00:00:00+00:00 [queued]>
[2024-07-10T13:23:49.529+0000] {taskinstance.py:2306} INFO - Starting attempt 1 of 6
[2024-07-10T13:23:49.546+0000] {taskinstance.py:2330} INFO - Executing <Task(PythonOperator): loading_into_db> on 2024-07-09 00:00:00+00:00
[2024-07-10T13:23:49.554+0000] {warnings.py:112} WARNING - /home/***/.local/lib/python3.12/site-packages/***/task/task_runner/standard_task_runner.py:61: DeprecationWarning: This process (pid=1410) is multi-threaded, use of fork() may lead to deadlocks in the child.
  pid = os.fork()

[2024-07-10T13:23:49.555+0000] {standard_task_runner.py:63} INFO - Started process 1412 to run task
[2024-07-10T13:23:49.555+0000] {standard_task_runner.py:90} INFO - Running: ['***', 'tasks', 'run', 'spaceX_project', 'loading_into_db', 'scheduled__2024-07-09T00:00:00+00:00', '--job-id', '589', '--raw', '--subdir', 'DAGS_FOLDER/dag.py', '--cfg-path', '/tmp/tmpx5sc2k6j']
[2024-07-10T13:23:49.558+0000] {standard_task_runner.py:91} INFO - Job 589: Subtask loading_into_db
[2024-07-10T13:23:49.611+0000] {task_command.py:426} INFO - Running <TaskInstance: spaceX_project.loading_into_db scheduled__2024-07-09T00:00:00+00:00 [running]> on host afe5e479c9b4
[2024-07-10T13:23:49.715+0000] {taskinstance.py:2648} INFO - Exporting env vars: AIRFLOW_CTX_DAG_OWNER='rustam' AIRFLOW_CTX_DAG_ID='spaceX_project' AIRFLOW_CTX_TASK_ID='loading_into_db' AIRFLOW_CTX_EXECUTION_DATE='2024-07-09T00:00:00+00:00' AIRFLOW_CTX_TRY_NUMBER='1' AIRFLOW_CTX_DAG_RUN_ID='scheduled__2024-07-09T00:00:00+00:00'
[2024-07-10T13:23:49.717+0000] {taskinstance.py:430} INFO - ::endgroup::
[2024-07-10T13:23:49.745+0000] {taskinstance.py:441} INFO - ::group::Post task execution logs
[2024-07-10T13:23:49.746+0000] {taskinstance.py:2905} ERROR - Task failed with exception
Traceback (most recent call last):
  File "/home/airflow/.local/lib/python3.12/site-packages/airflow/models/taskinstance.py", line 465, in _execute_task
    result = _execute_callable(context=context, **execute_callable_kwargs)
             ^^^^^^^^^^^^^^^^^^^^^^^^^^^^^^^^^^^^^^^^^^^^^^^^^^^^^^^^^^^^^
  File "/home/airflow/.local/lib/python3.12/site-packages/airflow/models/taskinstance.py", line 432, in _execute_callable
    return execute_callable(context=context, **execute_callable_kwargs)
           ^^^^^^^^^^^^^^^^^^^^^^^^^^^^^^^^^^^^^^^^^^^^^^^^^^^^^^^^^^^^
  File "/home/airflow/.local/lib/python3.12/site-packages/airflow/models/baseoperator.py", line 401, in wrapper
    return func(self, *args, **kwargs)
           ^^^^^^^^^^^^^^^^^^^^^^^^^^^
  File "/home/airflow/.local/lib/python3.12/site-packages/airflow/operators/python.py", line 235, in execute
    return_value = self.execute_callable()
                   ^^^^^^^^^^^^^^^^^^^^^^^
  File "/home/airflow/.local/lib/python3.12/site-packages/airflow/operators/python.py", line 252, in execute_callable
    return self.python_callable(*self.op_args, **self.op_kwargs)
           ^^^^^^^^^^^^^^^^^^^^^^^^^^^^^^^^^^^^^^^^^^^^^^^^^^^^^
  File "/opt/airflow/dags/dag.py", line 57, in load_charachteristics
    conn = psycopg2.connect(
           ^^^^^^^^^^^^^^^^^
  File "/home/airflow/.local/lib/python3.12/site-packages/psycopg2/__init__.py", line 122, in connect
    conn = _connect(dsn, connection_factory=connection_factory, **kwasync)
           ^^^^^^^^^^^^^^^^^^^^^^^^^^^^^^^^^^^^^^^^^^^^^^^^^^^^^^^^^^^^^^^
psycopg2.OperationalError: connection to server at "localhost" (127.0.0.1), port 5432 failed: Connection refused
	Is the server running on that host and accepting TCP/IP connections?
connection to server at "localhost" (::1), port 5432 failed: Cannot assign requested address
	Is the server running on that host and accepting TCP/IP connections?

[2024-07-10T13:23:49.764+0000] {taskinstance.py:1206} INFO - Marking task as UP_FOR_RETRY. dag_id=spaceX_project, task_id=loading_into_db, run_id=scheduled__2024-07-09T00:00:00+00:00, execution_date=20240709T000000, start_date=20240710T132349, end_date=20240710T132349
[2024-07-10T13:23:49.781+0000] {standard_task_runner.py:110} ERROR - Failed to execute job 589 for task loading_into_db (connection to server at "localhost" (127.0.0.1), port 5432 failed: Connection refused
	Is the server running on that host and accepting TCP/IP connections?
connection to server at "localhost" (::1), port 5432 failed: Cannot assign requested address
	Is the server running on that host and accepting TCP/IP connections?
; 1412)
[2024-07-10T13:23:49.810+0000] {local_task_job_runner.py:240} INFO - Task exited with return code 1
[2024-07-10T13:23:49.826+0000] {taskinstance.py:3503} INFO - 0 downstream tasks scheduled from follow-on schedule check
[2024-07-10T13:23:49.829+0000] {local_task_job_runner.py:222} INFO - ::endgroup::
