[2024-07-10T14:41:09.128+0000] {local_task_job_runner.py:120} INFO - ::group::Pre task execution logs
[2024-07-10T14:41:09.174+0000] {taskinstance.py:2076} INFO - Dependencies all met for dep_context=non-requeueable deps ti=<TaskInstance: spaceX_project.loading_into_db scheduled__2024-07-09T00:00:00+00:00 [queued]>
[2024-07-10T14:41:09.188+0000] {taskinstance.py:2076} INFO - Dependencies all met for dep_context=requeueable deps ti=<TaskInstance: spaceX_project.loading_into_db scheduled__2024-07-09T00:00:00+00:00 [queued]>
[2024-07-10T14:41:09.189+0000] {taskinstance.py:2306} INFO - Starting attempt 10 of 14
[2024-07-10T14:41:09.209+0000] {taskinstance.py:2330} INFO - Executing <Task(PythonOperator): loading_into_db> on 2024-07-09 00:00:00+00:00
[2024-07-10T14:41:09.221+0000] {warnings.py:112} WARNING - /home/***/.local/lib/python3.12/site-packages/***/task/task_runner/standard_task_runner.py:61: DeprecationWarning: This process (pid=634) is multi-threaded, use of fork() may lead to deadlocks in the child.
  pid = os.fork()

[2024-07-10T14:41:09.223+0000] {standard_task_runner.py:63} INFO - Started process 636 to run task
[2024-07-10T14:41:09.225+0000] {standard_task_runner.py:90} INFO - Running: ['***', 'tasks', 'run', 'spaceX_project', 'loading_into_db', 'scheduled__2024-07-09T00:00:00+00:00', '--job-id', '599', '--raw', '--subdir', 'DAGS_FOLDER/dag.py', '--cfg-path', '/tmp/tmpy5tdt6rq']
[2024-07-10T14:41:09.227+0000] {standard_task_runner.py:91} INFO - Job 599: Subtask loading_into_db
[2024-07-10T14:41:09.292+0000] {task_command.py:426} INFO - Running <TaskInstance: spaceX_project.loading_into_db scheduled__2024-07-09T00:00:00+00:00 [running]> on host 1831119bf87f
[2024-07-10T14:41:09.393+0000] {taskinstance.py:2648} INFO - Exporting env vars: AIRFLOW_CTX_DAG_OWNER='rustam' AIRFLOW_CTX_DAG_ID='spaceX_project' AIRFLOW_CTX_TASK_ID='loading_into_db' AIRFLOW_CTX_EXECUTION_DATE='2024-07-09T00:00:00+00:00' AIRFLOW_CTX_TRY_NUMBER='10' AIRFLOW_CTX_DAG_RUN_ID='scheduled__2024-07-09T00:00:00+00:00'
[2024-07-10T14:41:09.394+0000] {taskinstance.py:430} INFO - ::endgroup::
[2024-07-10T14:41:09.423+0000] {taskinstance.py:441} INFO - ::group::Post task execution logs
[2024-07-10T14:41:09.424+0000] {taskinstance.py:2905} ERROR - Task failed with exception
Traceback (most recent call last):
  File "/home/airflow/.local/lib/python3.12/site-packages/airflow/models/taskinstance.py", line 465, in _execute_task
    result = _execute_callable(context=context, **execute_callable_kwargs)
             ^^^^^^^^^^^^^^^^^^^^^^^^^^^^^^^^^^^^^^^^^^^^^^^^^^^^^^^^^^^^^
  File "/home/airflow/.local/lib/python3.12/site-packages/airflow/models/taskinstance.py", line 432, in _execute_callable
    return execute_callable(context=context, **execute_callable_kwargs)
           ^^^^^^^^^^^^^^^^^^^^^^^^^^^^^^^^^^^^^^^^^^^^^^^^^^^^^^^^^^^^
  File "/home/airflow/.local/lib/python3.12/site-packages/airflow/models/baseoperator.py", line 401, in wrapper
    return func(self, *args, **kwargs)
           ^^^^^^^^^^^^^^^^^^^^^^^^^^^
  File "/home/airflow/.local/lib/python3.12/site-packages/airflow/operators/python.py", line 235, in execute
    return_value = self.execute_callable()
                   ^^^^^^^^^^^^^^^^^^^^^^^
  File "/home/airflow/.local/lib/python3.12/site-packages/airflow/operators/python.py", line 252, in execute_callable
    return self.python_callable(*self.op_args, **self.op_kwargs)
           ^^^^^^^^^^^^^^^^^^^^^^^^^^^^^^^^^^^^^^^^^^^^^^^^^^^^^
  File "/opt/airflow/dags/dag.py", line 59, in load_charachteristics
    df = pd.read_csv('/mnt/c/Users/User/Downloads/SpaceX_project/charachteristics.csv')
         ^^^^^^^^^^^^^^^^^^^^^^^^^^^^^^^^^^^^^^^^^^^^^^^^^^^^^^^^^^^^^^^^^^^^^^^^^^^^^^
  File "/home/airflow/.local/lib/python3.12/site-packages/pandas/io/parsers/readers.py", line 948, in read_csv
    return _read(filepath_or_buffer, kwds)
           ^^^^^^^^^^^^^^^^^^^^^^^^^^^^^^^
  File "/home/airflow/.local/lib/python3.12/site-packages/pandas/io/parsers/readers.py", line 611, in _read
    parser = TextFileReader(filepath_or_buffer, **kwds)
             ^^^^^^^^^^^^^^^^^^^^^^^^^^^^^^^^^^^^^^^^^^
  File "/home/airflow/.local/lib/python3.12/site-packages/pandas/io/parsers/readers.py", line 1448, in __init__
    self._engine = self._make_engine(f, self.engine)
                   ^^^^^^^^^^^^^^^^^^^^^^^^^^^^^^^^^
  File "/home/airflow/.local/lib/python3.12/site-packages/pandas/io/parsers/readers.py", line 1705, in _make_engine
    self.handles = get_handle(
                   ^^^^^^^^^^^
  File "/home/airflow/.local/lib/python3.12/site-packages/pandas/io/common.py", line 863, in get_handle
    handle = open(
             ^^^^^
FileNotFoundError: [Errno 2] No such file or directory: '/mnt/c/Users/User/Downloads/SpaceX_project/charachteristics.csv'
[2024-07-10T14:41:09.444+0000] {taskinstance.py:1206} INFO - Marking task as UP_FOR_RETRY. dag_id=spaceX_project, task_id=loading_into_db, run_id=scheduled__2024-07-09T00:00:00+00:00, execution_date=20240709T000000, start_date=20240710T144109, end_date=20240710T144109
[2024-07-10T14:41:09.459+0000] {standard_task_runner.py:110} ERROR - Failed to execute job 599 for task loading_into_db ([Errno 2] No such file or directory: '/mnt/c/Users/User/Downloads/SpaceX_project/charachteristics.csv'; 636)
[2024-07-10T14:41:09.478+0000] {local_task_job_runner.py:240} INFO - Task exited with return code 1
[2024-07-10T14:41:09.495+0000] {taskinstance.py:3503} INFO - 0 downstream tasks scheduled from follow-on schedule check
[2024-07-10T14:41:09.497+0000] {local_task_job_runner.py:222} INFO - ::endgroup::
