[2024-07-11T13:06:31.410+0000] {local_task_job_runner.py:120} INFO - ::group::Pre task execution logs
[2024-07-11T13:06:31.445+0000] {taskinstance.py:2076} INFO - Dependencies all met for dep_context=non-requeueable deps ti=<TaskInstance: practise.inserting_into_table manual__2024-07-11T13:02:22.213405+00:00 [queued]>
[2024-07-11T13:06:31.457+0000] {taskinstance.py:2076} INFO - Dependencies all met for dep_context=requeueable deps ti=<TaskInstance: practise.inserting_into_table manual__2024-07-11T13:02:22.213405+00:00 [queued]>
[2024-07-11T13:06:31.458+0000] {taskinstance.py:2306} INFO - Starting attempt 2 of 7
[2024-07-11T13:06:31.476+0000] {taskinstance.py:2330} INFO - Executing <Task(PostgresOperator): inserting_into_table> on 2024-07-11 13:02:22.213405+00:00
[2024-07-11T13:06:31.484+0000] {warnings.py:112} WARNING - /home/***/.local/lib/python3.12/site-packages/***/task/task_runner/standard_task_runner.py:61: DeprecationWarning: This process (pid=168) is multi-threaded, use of fork() may lead to deadlocks in the child.
  pid = os.fork()

[2024-07-11T13:06:31.486+0000] {standard_task_runner.py:63} INFO - Started process 169 to run task
[2024-07-11T13:06:31.486+0000] {standard_task_runner.py:90} INFO - Running: ['***', 'tasks', 'run', 'practise', 'inserting_into_table', 'manual__2024-07-11T13:02:22.213405+00:00', '--job-id', '612', '--raw', '--subdir', 'DAGS_FOLDER/dag2.py', '--cfg-path', '/tmp/tmp2ngr7oz7']
[2024-07-11T13:06:31.488+0000] {standard_task_runner.py:91} INFO - Job 612: Subtask inserting_into_table
[2024-07-11T13:06:31.537+0000] {task_command.py:426} INFO - Running <TaskInstance: practise.inserting_into_table manual__2024-07-11T13:02:22.213405+00:00 [running]> on host b646c1147844
[2024-07-11T13:06:31.657+0000] {taskinstance.py:2648} INFO - Exporting env vars: AIRFLOW_CTX_DAG_OWNER='papik' AIRFLOW_CTX_DAG_ID='practise' AIRFLOW_CTX_TASK_ID='inserting_into_table' AIRFLOW_CTX_EXECUTION_DATE='2024-07-11T13:02:22.213405+00:00' AIRFLOW_CTX_TRY_NUMBER='2' AIRFLOW_CTX_DAG_RUN_ID='manual__2024-07-11T13:02:22.213405+00:00'
[2024-07-11T13:06:31.658+0000] {taskinstance.py:430} INFO - ::endgroup::
[2024-07-11T13:06:31.680+0000] {sql.py:276} INFO - Executing: 
            INSERT INTO tab(id,txt)
            VALUES
            (1,'df'),
            (2,'dss'),
            (3,'fds');
        
[2024-07-11T13:06:31.695+0000] {base.py:84} INFO - Using connection ID 'cosmos' for task execution.
[2024-07-11T13:06:31.709+0000] {base.py:84} INFO - Using connection ID 'cosmos' for task execution.
[2024-07-11T13:06:31.713+0000] {sql.py:487} INFO - Running statement: 
            INSERT INTO tab(id,txt)
            VALUES
            (1,'df'),
            (2,'dss'),
            (3,'fds');
        , parameters: None
[2024-07-11T13:06:31.716+0000] {taskinstance.py:441} INFO - ::group::Post task execution logs
[2024-07-11T13:06:31.717+0000] {taskinstance.py:2905} ERROR - Task failed with exception
Traceback (most recent call last):
  File "/home/airflow/.local/lib/python3.12/site-packages/airflow/models/taskinstance.py", line 465, in _execute_task
    result = _execute_callable(context=context, **execute_callable_kwargs)
             ^^^^^^^^^^^^^^^^^^^^^^^^^^^^^^^^^^^^^^^^^^^^^^^^^^^^^^^^^^^^^
  File "/home/airflow/.local/lib/python3.12/site-packages/airflow/models/taskinstance.py", line 432, in _execute_callable
    return execute_callable(context=context, **execute_callable_kwargs)
           ^^^^^^^^^^^^^^^^^^^^^^^^^^^^^^^^^^^^^^^^^^^^^^^^^^^^^^^^^^^^
  File "/home/airflow/.local/lib/python3.12/site-packages/airflow/models/baseoperator.py", line 401, in wrapper
    return func(self, *args, **kwargs)
           ^^^^^^^^^^^^^^^^^^^^^^^^^^^
  File "/home/airflow/.local/lib/python3.12/site-packages/airflow/providers/common/sql/operators/sql.py", line 282, in execute
    output = hook.run(
             ^^^^^^^^^
  File "/home/airflow/.local/lib/python3.12/site-packages/airflow/providers/common/sql/hooks/sql.py", line 435, in run
    self._run_command(cur, sql_statement, parameters)
  File "/home/airflow/.local/lib/python3.12/site-packages/airflow/providers/common/sql/hooks/sql.py", line 492, in _run_command
    cur.execute(sql_statement)
psycopg2.errors.UniqueViolation: duplicate key value violates unique constraint "tab_pkey"
DETAIL:  Key (id)=(1) already exists.

[2024-07-11T13:06:31.729+0000] {taskinstance.py:1206} INFO - Marking task as UP_FOR_RETRY. dag_id=practise, task_id=inserting_into_table, run_id=manual__2024-07-11T13:02:22.213405+00:00, execution_date=20240711T130222, start_date=20240711T130631, end_date=20240711T130631
[2024-07-11T13:06:31.745+0000] {standard_task_runner.py:110} ERROR - Failed to execute job 612 for task inserting_into_table (duplicate key value violates unique constraint "tab_pkey"
DETAIL:  Key (id)=(1) already exists.
; 169)
[2024-07-11T13:06:31.783+0000] {local_task_job_runner.py:240} INFO - Task exited with return code 1
[2024-07-11T13:06:31.806+0000] {taskinstance.py:3503} INFO - 0 downstream tasks scheduled from follow-on schedule check
[2024-07-11T13:06:31.808+0000] {local_task_job_runner.py:222} INFO - ::endgroup::
